Workbook

Sheet SP500
A1: observation_date | B1: SP500 | C1: SP500 1 day return | D1: SP500 3 day momentum | E1: VIX | F1: VIX 1 day change | G1: DGS10 | H1: DGS10 1 day change | I1: T10Y3M | J1: BAMLC0A4CBBB | K1: CPIAUCSL | L1: DFF | M1: DGS2 | N1: DGS2 1 day change | O1: Target: Raw next-day return | P1: Target: Up or Down - 1 next day UP, 0 next day down/flat | Q1: Target: Buy/hold/sell = 1/0/-1 0.3% margin | R1: Closing Value - CRUDE OIL
A2: 42464 | B2: 2066.13 | E2: =_xlfn.XLOOKUP(A2,VIX!A:A,VIX!B:B,"",-1) -> 14.12 | G2: =_xlfn.XLOOKUP(A2,'DGS10'!A:A,'DGS10'!B:B,"",-1) -> 1.78 | I2: =_xlfn.XLOOKUP(A2,T10Y3M!A:A,T10Y3M!B:B,"",-1) -> 1.55 | J2: =_xlfn.XLOOKUP(A2,BAMLC0A4CBBB!A:A,BAMLC0A4CBBB!B:B,"",-1) -> 2.3 | K2: =_xlfn.XLOOKUP(A2,CPIAUCSL!A:A,CPIAUCSL!B:B,"",-1) -> 238.992 | L2: =_xlfn.XLOOKUP(A2,DFF!A:A,DFF!B:B,"",-1) -> 0.37 | M2: =_xlfn.XLOOKUP(A2,'DGS2'!A:A,'DGS2'!B:B,"",-1) -> 0.75 | R2: 35.7
A3: 42465 | B3: 2045.17 | C3: =IF(OR(B3="",B2=""),"",(B3/B2)-1) -> -0.01014457 | E3: =_xlfn.XLOOKUP(A3,VIX!A:A,VIX!B:B,"",-1) -> 15.42 | F3: =IF(OR(E3="",E2=""),"",E3-E2) -> 1.3 | G3: =_xlfn.XLOOKUP(A3,'DGS10'!A:A,'DGS10'!B:B,"",-1) -> 1.73 | H3: =IF(OR(G3="",G2=""),"",G3-G2) -> -0.05 | I3: =_xlfn.XLOOKUP(A3,T10Y3M!A:A,T10Y3M!B:B,"",-1) -> 1.5 | J3: =_xlfn.XLOOKUP(A3,BAMLC0A4CBBB!A:A,BAMLC0A4CBBB!B:B,"",-1) -> 2.31 | K3: =_xlfn.XLOOKUP(A3,CPIAUCSL!A:A,CPIAUCSL!B:B,"",-1) -> 238.992 | L3: =_xlfn.XLOOKUP(A3,DFF!A:A,DFF!B:B,"",-1) -> 0.37 | M3: =_xlfn.XLOOKUP(A3,'DGS2'!A:A,'DGS2'!B:B,"",-1) -> 0.72 | N3: =IF(OR(M3="",M2=""),"",M3-M2) -> -0.03 | O3: =IF(OR(B4="",B3=""),"",(B4/B3)-1) -> 0.010507684 | P3: =IF(O3="","",IF(O3>0,1,0)) -> 1 | Q3: =IF(O3="","",IF(O3>0.003,1,IF(O3<-0.01,-1,0))) -> 1 | R3: 35.89
A4: 42466 | B4: 2066.66 | C4: =IF(OR(B4="",B3=""),"",(B4/B3)-1) -> 0.010507684 | E4: =_xlfn.XLOOKUP(A4,VIX!A:A,VIX!B:B,"",-1) -> 14.09 | F4: =IF(OR(E4="",E3=""),"",E4-E3) -> -1.33 | G4: =_xlfn.XLOOKUP(A4,'DGS10'!A:A,'DGS10'!B:B,"",-1) -> 1.76 | H4: =IF(OR(G4="",G3=""),"",G4-G3) -> 0.03 | I4: =_xlfn.XLOOKUP(A4,T10Y3M!A:A,T10Y3M!B:B,"",-1) -> 1.53 | J4: =_xlfn.XLOOKUP(A4,BAMLC0A4CBBB!A:A,BAMLC0A4CBBB!B:B,"",-1) -> 2.3 | K4: =_xlfn.XLOOKUP(A4,CPIAUCSL!A:A,CPIAUCSL!B:B,"",-1) -> 238.992 | L4: =_xlfn.XLOOKUP(A4,DFF!A:A,DFF!B:B,"",-1) -> 0.37 | M4: =_xlfn.XLOOKUP(A4,'DGS2'!A:A,'DGS2'!B:B,"",-1) -> 0.73 | N4: =IF(OR(M4="",M3=""),"",M4-M3) -> 0.01 | O4: =IF(OR(B5="",B4=""),"",(B5/B4)-1) -> -0.011975845 | P4: =IF(O4="","",IF(O4>0,1,0)) -> 0 | Q4: =IF(O4="","",IF(O4>0.003,1,IF(O4<-0.003,-1,0))) -> -1 | R4: 37.75
A5: 42467 | B5: 2041.91 | C5: =IF(OR(B5="",B4=""),"",(B5/B4)-1) -> -0.011975845 | D5: =IF(OR(B5="",B2=""),"",(B5/B2)-1) -> -0.011722399 | E5: =_xlfn.XLOOKUP(A5,VIX!A:A,VIX!B:B,"",-1) -> 16.16 | F5: =IF(OR(E5="",E4=""),"",E5-E4) -> 2.07 | G5: =_xlfn.XLOOKUP(A5,'DGS10'!A:A,'DGS10'!B:B,"",-1) -> 1.7 | H5: =IF(OR(G5="",G4=""),"",G5-G4) -> -0.06 | I5: =_xlfn.XLOOKUP(A5,T10Y3M!A:A,T10Y3M!B:B,"",-1) -> 1.47 | J5: =_xlfn.XLOOKUP(A5,BAMLC0A4CBBB!A:A,BAMLC0A4CBBB!B:B,"",-1) -> 2.31 | K5: =_xlfn.XLOOKUP(A5,CPIAUCSL!A:A,CPIAUCSL!B:B,"",-1) -> 238.992 | L5: =_xlfn.XLOOKUP(A5,DFF!A:A,DFF!B:B,"",-1) -> 0.37 | M5: =_xlfn.XLOOKUP(A5,'DGS2'!A:A,'DGS2'!B:B,"",-1) -> 0.7 | N5: =IF(OR(M5="",M4=""),"",M5-M4) -> -0.03 | O5: =IF(OR(B6="",B5=""),"",(B6/B5)-1) -> 0.0027866067 | P5: =IF(O5="","",IF(O5>0,1,0)) -> 1 | Q5: =IF(O5="","",IF(O5>0.003,1,IF(O5<-0.003,-1,0))) -> 0 | R5: 37.26
A6: 42468 | B6: 2047.6 | C6: =IF(OR(B6="",B5=""),"",(B6/B5)-1) -> 0.0027866067 | D6: =IF(OR(B6="",B3=""),"",(B6/B3)-1) -> 0.0011881653 | E6: =_xlfn.XLOOKUP(A6,VIX!A:A,VIX!B:B,"",-1) -> 15.36 | F6: =IF(OR(E6="",E5=""),"",E6-E5) -> -0.8 | G6: =_xlfn.XLOOKUP(A6,'DGS10'!A:A,'DGS10'!B:B,"",-1) -> 1.72 | H6: =IF(OR(G6="",G5=""),"",G6-G5) -> 0.02 | I6: =_xlfn.XLOOKUP(A6,T10Y3M!A:A,T10Y3M!B:B,"",-1) -> 1.49 | J6: =_xlfn.XLOOKUP(A6,BAMLC0A4CBBB!A:A,BAMLC0A4CBBB!B:B,"",-1) -> 2.31 | K6: =_xlfn.XLOOKUP(A6,CPIAUCSL!A:A,CPIAUCSL!B:B,"",-1) -> 238.992 | L6: =_xlfn.XLOOKUP(A6,DFF!A:A,DFF!B:B,"",-1) -> 0.37 | M6: =_xlfn.XLOOKUP(A6,'DGS2'!A:A,'DGS2'!B:B,"",-1) -> 0.7 | N6: =IF(OR(M6="",M5=""),"",M6-M5) -> 0 | O6: =IF(OR(B7="",B6=""),"",(B7/B6)-1) -> -0.0027397929 | P6: =IF(O6="","",IF(O6>0,1,0)) -> 0 | Q6: =IF(O6="","",IF(O6>0.003,1,IF(O6<-0.003,-1,0))) -> 0 | R6: 39.72
A7: 42471 | B7: 2041.99 | C7: =IF(OR(B7="",B6=""),"",(B7/B6)-1) -> -0.0027397929 | D7: =IF(OR(B7="",B4=""),"",(B7/B4)-1) -> -0.011937135 | E7: =_xlfn.XLOOKUP(A7,VIX!A:A,VIX!B:B,"",-1) -> 16.26 | F7: =IF(OR(E7="",E6=""),"",E7-E6) -> 0.9 | G7: =_xlfn.XLOOKUP(A7,'DGS10'!A:A,'DGS10'!B:B,"",-1) -> 1.73 | H7: =IF(OR(G7="",G6=""),"",G7-G6) -> 0.01 | I7: =_xlfn.XLOOKUP(A7,T10Y3M!A:A,T10Y3M!B:B,"",-1) -> 1.5 | J7: =_xlfn.XLOOKUP(A7,BAMLC0A4CBBB!A:A,BAMLC0A4CBBB!B:B,"",-1) -> 2.3 | K7: =_xlfn.XLOOKUP(A7,CPIAUCSL!A:A,CPIAUCSL!B:B,"",-1) -> 238.992 | L7: =_xlfn.XLOOKUP(A7,DFF!A:A,DFF!B:B,"",-1) -> 0.37 | M7: =_xlfn.XLOOKUP(A7,'DGS2'!A:A,'DGS2'!B:B,"",-1) -> 0.7 | N7: =IF(OR(M7="",M6=""),"",M7-M6) -> 0 | O7: =IF(OR(B8="",B7=""),"",(B8/B7)-1) -> 0.0096621433 | P7: =IF(O7="","",IF(O7>0,1,0)) -> 1 | Q7: =IF(O7="","",IF(O7>0.003,1,IF(O7<-0.003,-1,0))) -> 1 | R7: 40.36
A8: 42472 | B8: 2061.72 | C8: =IF(OR(B8="",B7=""),"",(B8/B7)-1) -> 0.0096621433 | D8: =IF(OR(B8="",B5=""),"",(B8/B5)-1) -> 0.0097017009 | E8: =_xlfn.XLOOKUP(A8,VIX!A:A,VIX!B:B,"",-1) -> 14.85 | F8: =IF(OR(E8="",E7=""),"",E8-E7) -> -1.41 | G8: =_xlfn.XLOOKUP(A8,'DGS10'!A:A,'DGS10'!B:B,"",-1) -> 1.79 | H8: =IF(OR(G8="",G7=""),"",G8-G7) -> 0.06 | I8: =_xlfn.XLOOKUP(A8,T10Y3M!A:A,T10Y3M!B:B,"",-1) -> 1.57 | J8: =_xlfn.XLOOKUP(A8,BAMLC0A4CBBB!A:A,BAMLC0A4CBBB!B:B,"",-1) -> 2.28 | K8: =_xlfn.XLOOKUP(A8,CPIAUCSL!A:A,CPIAUCSL!B:B,"",-1) -> 238.992 | L8: =_xlfn.XLOOKUP(A8,DFF!A:A,DFF!B:B,"",-1) -> 0.37 | M8: =_xlfn.XLOOKUP(A8,'DGS2'!A:A,'DGS2'!B:B,"",-1) -> 0.74 | N8: =IF(OR(M8="",M7=""),"",M8-M7) -> 0.04 | O8: =IF(OR(B9="",B8=""),"",(B9/B8)-1) -> 0.010040161 | P8: =IF(O8="","",IF(O8>0,1,0)) -> 1 | Q8: =IF(O8="","",IF(O8>0.003,1,IF(O8<-0.003,-1,0))) -> 1 | R8: 42.17
A9: 42473 | B9: 2082.42 | C9: =IF(OR(B9="",B8=""),"",(B9/B8)-1) -> 0.010040161 | D9: =IF(OR(B9="",B6=""),"",(B9/B6)-1) -> 0.017005274 | E9: =_xlfn.XLOOKUP(A9,VIX!A:A,VIX!B:B,"",-1) -> 13.84 | F9: =IF(OR(E9="",E8=""),"",E9-E8) -> -1.01 | G9: =_xlfn.XLOOKUP(A9,'DGS10'!A:A,'DGS10'!B:B,"",-1) -> 1.77 | H9: =IF(OR(G9="",G8=""),"",G9-G8) -> -0.02 | I9: =_xlfn.XLOOKUP(A9,T10Y3M!A:A,T10Y3M!B:B,"",-1) -> 1.54 | J9: =_xlfn.XLOOKUP(A9,BAMLC0A4CBBB!A:A,BAMLC0A4CBBB!B:B,"",-1) -> 2.26 | K9: =_xlfn.XLOOKUP(A9,CPIAUCSL!A:A,CPIAUCSL!B:B,"",-1) -> 238.992 | L9: =_xlfn.XLOOKUP(A9,DFF!A:A,DFF!B:B,"",-1) -> 0.37 | M9: =_xlfn.XLOOKUP(A9,'DGS2'!A:A,'DGS2'!B:B,"",-1) -> 0.75 | N9: =IF(OR(M9="",M8=""),"",M9-M8) -> 0.01 | O9: =IF(OR(B10="",B9=""),"",(B10/B9)-1) -> 0.00017287579 | P9: =IF(O9="","",IF(O9>0,1,0)) -> 1 | Q9: =IF(O9="","",IF(O9>0.003,1,IF(O9<-0.003,-1,0))) -> 0 | R9: 41.76
A10: 42474 | B10: 2082.78 | C10: =IF(OR(B10="",B9=""),"",(B10/B9)-1) -> 0.00017287579 | D10: =IF(OR(B10="",B7=""),"",(B10/B7)-1) -> 0.019975612 | E10: =_xlfn.XLOOKUP(A10,VIX!A:A,VIX!B:B,"",-1) -> 13.72 | F10: =IF(OR(E10="",E9=""),"",E10-E9) -> -0.12 | G10: =_xlfn.XLOOKUP(A10,'DGS10'!A:A,'DGS10'!B:B,"",-1) -> 1.8 | H10: =IF(OR(G10="",G9=""),"",G10-G9) -> 0.03 | I10: =_xlfn.XLOOKUP(A10,T10Y3M!A:A,T10Y3M!B:B,"",-1) -> 1.58 | J10: =_xlfn.XLOOKUP(A10,BAMLC0A4CBBB!A:A,BAMLC0A4CBBB!B:B,"",-1) -> 2.23 | K10: =_xlfn.XLOOKUP(A10,CPIAUCSL!A:A,CPIAUCSL!B:B,"",-1) -> 238.992 | L10: =_xlfn.XLOOKUP(A10,DFF!A:A,DFF!B:B,"",-1) -> 0.37 | M10: =_xlfn.XLOOKUP(A10,'DGS2'!A:A,'DGS2'!B:B,"",-1) -> 0.77 | N10: =IF(OR(M10="",M9=""),"",M10-M9) -> 0.02 | O10: =IF(OR(B11="",B10=""),"",(B11/B10)-1) -> -0.00098426142 | P10: =IF(O10="","",IF(O10>0,1,0)) -> 0 | Q10: =IF(O10="","",IF(O10>0.003,1,IF(O10<-0.003,-1,0))) -> 0 | R10: 41.5
A11: 42475 | B11: 2080.73 | C11: =IF(OR(B11="",B10=""),"",(B11/B10)-1) -> -0.00098426142 | D11: =IF(OR(B11="",B8=""),"",(B11/B8)-1) -> 0.0092204567 | E11: =_xlfn.XLOOKUP(A11,VIX!A:A,VIX!B:B,"",-1) -> 13.62 | F11: =IF(OR(E11="",E10=""),"",E11-E10) -> -0.1 | G11: =_xlfn.XLOOKUP(A11,'DGS10'!A:A,'DGS10'!B:B,"",-1) -> 1.76 | H11: =IF(OR(G11="",G10=""),"",G11-G10) -> -0.04 | I11: =_xlfn.XLOOKUP(A11,T10Y3M!A:A,T10Y3M!B:B,"",-1) -> 1.54 | J11: =_xlfn.XLOOKUP(A11,BAMLC0A4CBBB!A:A,BAMLC0A4CBBB!B:B,"",-1) -> 2.22 | K11: =_xlfn.XLOOKUP(A11,CPIAUCSL!A:A,CPIAUCSL!B:B,"",-1) -> 238.992 | L11: =_xlfn.XLOOKUP(A11,DFF!A:A,DFF!B:B,"",-1) -> 0.37 | M11: =_xlfn.XLOOKUP(A11,'DGS2'!A:A,'DGS2'!B:B,"",-1) -> 0.74 | N11: =IF(OR(M11="",M10=""),"",M11-M10) -> -0.03 | O11: =IF(OR(B12="",B11=""),"",(B12/B11)-1) -> 0.0065409736 | P11: =IF(O11="","",IF(O11>0,1,0)) -> 1 | Q11: =IF(O11="","",IF(O11>0.003,1,IF(O11<-0.003,-1,0))) -> 1 | R11: 40.36
A12: 42478 | B12: 2094.34 | C12: =IF(OR(B12="",B11=""),"",(B12/B11)-1) -> 0.0065409736 | D12: =IF(OR(B12="",B9=""),"",(B12/B9)-1) -> 0.0057241094 | E12: =_xlfn.XLOOKUP(A12,VIX!A:A,VIX!B:B,"",-1) -> 13.35 | F12: =IF(OR(E12="",E11=""),"",E12-E11) -> -0.27 | G12: =_xlfn.XLOOKUP(A12,'DGS10'!A:A,'DGS10'!B:B,"",-1) -> 1.78 | H12: =IF(OR(G12="",G11=""),"",G12-G11) -> 0.02 | I12: =_xlfn.XLOOKUP(A12,T10Y3M!A:A,T10Y3M!B:B,"",-1) -> 1.56 | J12: =_xlfn.XLOOKUP(A12,BAMLC0A4CBBB!A:A,BAMLC0A4CBBB!B:B,"",-1) -> 2.21 | K12: =_xlfn.XLOOKUP(A12,CPIAUCSL!A:A,CPIAUCSL!B:B,"",-1) -> 238.992 | L12: =_xlfn.XLOOKUP(A12,DFF!A:A,DFF!B:B,"",-1) -> 0.37 | M12: =_xlfn.XLOOKUP(A12,'DGS2'!A:A,'DGS2'!B:B,"",-1) -> 0.75 | N12: =IF(OR(M12="",M11=""),"",M12-M11) -> 0.01 | O12: =IF(OR(B13="",B12=""),"",(B13/B12)-1) -> 0.0030845039 | P12: =IF(O12="","",IF(O12>0,1,0)) -> 1 | Q12: =IF(O12="","",IF(O12>0.003,1,IF(O12<-0.003,-1,0))) -> 1 | R12: 39.78
A13: 42479 | B13: 2100.8 | C13: =IF(OR(B13="",B12=""),"",(B13/B12)-1) -> 0.0030845039 | D13: =IF(OR(B13="",B10=""),"",(B13/B10)-1) -> 0.0086518979 | E13: =_xlfn.XLOOKUP(A13,VIX!A:A,VIX!B:B,"",-1) -> 13.24 | F13: =IF(OR(E13="",E12=""),"",E13-E12) -> -0.11 | G13: =_xlfn.XLOOKUP(A13,'DGS10'!A:A,'DGS10'!B:B,"",-1) -> 1.79 | H13: =IF(OR(G13="",G12=""),"",G13-G12) -> 0.01 | I13: =_xlfn.XLOOKUP(A13,T10Y3M!A:A,T10Y3M!B:B,"",-1) -> 1.58 | J13: =_xlfn.XLOOKUP(A13,BAMLC0A4CBBB!A:A,BAMLC0A4CBBB!B:B,"",-1) -> 2.18 | K13: =_xlfn.XLOOKUP(A13,CPIAUCSL!A:A,CPIAUCSL!B:B,"",-1) -> 238.992 | L13: =_xlfn.XLOOKUP(A13,DFF!A:A,DFF!B:B,"",-1) -> 0.37 | M13: =_xlfn.XLOOKUP(A13,'DGS2'!A:A,'DGS2'!B:B,"",-1) -> 0.77 | N13: =IF(OR(M13="",M12=""),"",M13-M12) -> 0.02 | O13: =IF(OR(B14="",B13=""),"",(B14/B13)-1) -> 0.00076161462 | P13: =IF(O13="","",IF(O13>0,1,0)) -> 1 | Q13: =IF(O13="","",IF(O13>0.003,1,IF(O13<-0.003,-1,0))) -> 0 | R13: 41.08
A14: 42480 | B14: 2102.4 | C14: =IF(OR(B14="",B13=""),"",(B14/B13)-1) -> 0.00076161462 | D14: =IF(OR(B14="",B11=""),"",(B14/B11)-1) -> 0.010414614 | E14: =_xlfn.XLOOKUP(A14,VIX!A:A,VIX!B:B,"",-1) -> 13.28 | F14: =IF(OR(E14="",E13=""),"",E14-E13) -> 0.04 | G14: =_xlfn.XLOOKUP(A14,'DGS10'!A:A,'DGS10'!B:B,"",-1) -> 1.85 | H14: =IF(OR(G14="",G13=""),"",G14-G13) -> 0.06 | I14: =_xlfn.XLOOKUP(A14,T10Y3M!A:A,T10Y3M!B:B,"",-1) -> 1.62 | J14: =_xlfn.XLOOKUP(A14,BAMLC0A4CBBB!A:A,BAMLC0A4CBBB!B:B,"",-1) -> 2.14 | K14: =_xlfn.XLOOKUP(A14,CPIAUCSL!A:A,CPIAUCSL!B:B,"",-1) -> 238.992 | L14: =_xlfn.XLOOKUP(A14,DFF!A:A,DFF!B:B,"",-1) -> 0.37 | M14: =_xlfn.XLOOKUP(A14,'DGS2'!A:A,'DGS2'!B:B,"",-1) -> 0.8 | N14: =IF(OR(M14="",M13=""),"",M14-M13) -> 0.03 | O14: =IF(OR(B15="",B14=""),"",(B15/B14)-1) -> -0.0051940639 | P14: =IF(O14="","",IF(O14>0,1,0)) -> 0 | Q14: =IF(O14="","",IF(O14>0.003,1,IF(O14<-0.003,-1,0))) -> -1 | R14: 42.63
A15: 42481 | B15: 2091.48 | C15: =IF(OR(B15="",B14=""),"",(B15/B14)-1) -> -0.0051940639 | D15: =IF(OR(B15="",B12=""),"",(B15/B12)-1) -> -0.0013655853 | E15: =_xlfn.XLOOKUP(A15,VIX!A:A,VIX!B:B,"",-1) -> 13.95 | F15: =IF(OR(E15="",E14=""),"",E15-E14) -> 0.67 | G15: =_xlfn.XLOOKUP(A15,'DGS10'!A:A,'DGS10'!B:B,"",-1) -> 1.88 | H15: =IF(OR(G15="",G14=""),"",G15-G14) -> 0.03 | I15: =_xlfn.XLOOKUP(A15,T10Y3M!A:A,T10Y3M!B:B,"",-1) -> 1.65 | J15: =_xlfn.XLOOKUP(A15,BAMLC0A4CBBB!A:A,BAMLC0A4CBBB!B:B,"",-1) -> 2.11 | K15: =_xlfn.XLOOKUP(A15,CPIAUCSL!A:A,CPIAUCSL!B:B,"",-1) -> 238.992 | L15: =_xlfn.XLOOKUP(A15,DFF!A:A,DFF!B:B,"",-1) -> 0.37 | M15: =_xlfn.XLOOKUP(A15,'DGS2'!A:A,'DGS2'!B:B,"",-1) -> 0.82 | N15: =IF(OR(M15="",M14=""),"",M15-M14) -> 0.02 | O15: =IF(OR(B16="",B15=""),"",(B16/B15)-1) -> 4.7813032e-05 | P15: =IF(O15="","",IF(O15>0,1,0)) -> 1 | Q15: =IF(O15="","",IF(O15>0.003,1,IF(O15<-0.003,-1,0))) -> 0 | R15: 43.18
A16: 42482 | B16: 2091.58 | C16: =IF(OR(B16="",B15=""),"",(B16/B15)-1) -> 4.7813032e-05 | D16: =IF(OR(B16="",B13=""),"",(B16/B13)-1) -> -0.0043888043 | E16: =_xlfn.XLOOKUP(A16,VIX!A:A,VIX!B:B,"",-1) -> 13.22 | F16: =IF(OR(E16="",E15=""),"",E16-E15) -> -0.73 | G16: =_xlfn.XLOOKUP(A16,'DGS10'!A:A,'DGS10'!B:B,"",-1) -> 1.89 | H16: =IF(OR(G16="",G15=""),"",G16-G15) -> 0.01 | I16: =_xlfn.XLOOKUP(A16,T10Y3M!A:A,T10Y3M!B:B,"",-1) -> 1.66 | J16: =_xlfn.XLOOKUP(A16,BAMLC0A4CBBB!A:A,BAMLC0A4CBBB!B:B,"",-1) -> 2.09 | K16: =_xlfn.XLOOKUP(A16,CPIAUCSL!A:A,CPIAUCSL!B:B,"",-1) -> 238.992 | L16: =_xlfn.XLOOKUP(A16,DFF!A:A,DFF!B:B,"",-1) -> 0.37 | M16: =_xlfn.XLOOKUP(A16,'DGS2'!A:A,'DGS2'!B:B,"",-1) -> 0.84 | N16: =IF(OR(M16="",M15=""),"",M16-M15) -> 0.02 | O16: =IF(OR(B17="",B16=""),"",(B17/B16)-1) -> -0.0018120273 | P16: =IF(O16="","",IF(O16>0,1,0)) -> 0 | Q16: =IF(O16="","",IF(O16>0.003,1,IF(O16<-0.003,-1,0))) -> 0 | R16: 43.73
... A431: 43082 | B431: 2662.85 | C431: =IF(OR(B431="",B430=""),"",(B431/B430)-1) -> -0.00047295344 | D431: =IF(OR(B431="",B428=""),"",(B431/B428)-1) -> 0.0042805959 | E431: =_xlfn.XLOOKUP(A431,VIX!A:A,VIX!B:B,"",-1) -> 10.18 | F431: =IF(OR(E431="",E430=""),"",E431-E430) -> 0.26 | G431: =_xlfn.XLOOKUP(A431,'DGS10'!A:A,'DGS10'!B:B,"",-1) -> 2.36 | H431: =IF(OR(G431="",G430=""),"",G431-G430) -> -0.04 | I431: =_xlfn.XLOOKUP(A431,T10Y3M!A:A,T10Y3M!B:B,"",-1) -> 1.06 | J431: =_xlfn.XLOOKUP(A431,BAMLC0A4CBBB!A:A,BAMLC0A4CBBB!B:B,"",-1) -> 1.31 | K431: =_xlfn.XLOOKUP(A431,CPIAUCSL!A:A,CPIAUCSL!B:B,"",-1) -> 247.805 | L431: =_xlfn.XLOOKUP(A431,DFF!A:A,DFF!B:B,"",-1) -> 1.17 | M431: =_xlfn.XLOOKUP(A431,'DGS2'!A:A,'DGS2'!B:B,"",-1) -> 1.79 | N431: =IF(OR(M431="",M430=""),"",M431-M430) -> -0.04 | O431: =IF(OR(B432="",B431=""),"",(B432/B431)-1) -> -0.0040708264 | P431: =IF(O431="","",IF(O431>0,1,0)) -> 0 | Q431: =IF(O431="","",IF(O431>0.003,1,IF(O431<-0.003,-1,0))) -> -1 | R431: 58.02
A432: 43083 | B432: 2652.01 | C432: =IF(OR(B432="",B431=""),"",(B432/B431)-1) -> -0.0040708264 | D432: =IF(OR(B432="",B429=""),"",(B432/B429)-1) -> -0.0030000113 | E432: =_xlfn.XLOOKUP(A432,VIX!A:A,VIX!B:B,"",-1) -> 10.49 | F432: =IF(OR(E432="",E431=""),"",E432-E431) -> 0.31 | G432: =_xlfn.XLOOKUP(A432,'DGS10'!A:A,'DGS10'!B:B,"",-1) -> 2.35 | H432: =IF(OR(G432="",G431=""),"",G432-G431) -> -0.01 | I432: =_xlfn.XLOOKUP(A432,T10Y3M!A:A,T10Y3M!B:B,"",-1) -> 1.03 | J432: =_xlfn.XLOOKUP(A432,BAMLC0A4CBBB!A:A,BAMLC0A4CBBB!B:B,"",-1) -> 1.31 | K432: =_xlfn.XLOOKUP(A432,CPIAUCSL!A:A,CPIAUCSL!B:B,"",-1) -> 247.805 | L432: =_xlfn.XLOOKUP(A432,DFF!A:A,DFF!B:B,"",-1) -> 1.41 | M432: =_xlfn.XLOOKUP(A432,'DGS2'!A:A,'DGS2'!B:B,"",-1) -> 1.82 | N432: =IF(OR(M432="",M431=""),"",M432-M431) -> 0.03 | O432: =IF(OR(B433="",B432=""),"",(B433/B432)-1) -> 0.0089743251 | P432: =IF(O432="","",IF(O432>0,1,0)) -> 1 | Q432: =IF(O432="","",IF(O432>0.003,1,IF(O432<-0.003,-1,0))) -> 1
A433: 43084 | B433: 2675.81 | C433: =IF(OR(B433="",B432=""),"",(B433/B432)-1) -> 0.0089743251 | D433: =IF(OR(B433="",B430=""),"",(B433/B430)-1) -> 0.0043917106 | E433: =_xlfn.XLOOKUP(A433,VIX!A:A,VIX!B:B,"",-1) -> 9.42 | F433: =IF(OR(E433="",E432=""),"",E433-E432) -> -1.07 | G433: =_xlfn.XLOOKUP(A433,'DGS10'!A:A,'DGS10'!B:B,"",-1) -> 2.35 | H433: =IF(OR(G433="",G432=""),"",G433-G432) -> 0 | I433: =_xlfn.XLOOKUP(A433,T10Y3M!A:A,T10Y3M!B:B,"",-1) -> 1.04 | J433: =_xlfn.XLOOKUP(A433,BAMLC0A4CBBB!A:A,BAMLC0A4CBBB!B:B,"",-1) -> 1.3 | K433: =_xlfn.XLOOKUP(A433,CPIAUCSL!A:A,CPIAUCSL!B:B,"",-1) -> 247.805 | L433: =_xlfn.XLOOKUP(A433,DFF!A:A,DFF!B:B,"",-1) -> 1.41 | M433: =_xlfn.XLOOKUP(A433,'DGS2'!A:A,'DGS2'!B:B,"",-1) -> 1.84 | N433: =IF(OR(M433="",M432=""),"",M433-M432) -> 0.02 | O433: =IF(OR(B434="",B433=""),"",(B434/B433)-1) -> 0.0053628621 | P433: =IF(O433="","",IF(O433>0,1,0)) -> 1 | Q433: =IF(O433="","",IF(O433>0.003,1,IF(O433<-0.003,-1,0))) -> 1 | R433: 58.95
A434: 43087 | B434: 2690.16 | C434: =IF(OR(B434="",B433=""),"",(B434/B433)-1) -> 0.0053628621 | D434: =IF(OR(B434="",B431=""),"",(B434/B431)-1) -> 0.010255929 | E434: =_xlfn.XLOOKUP(A434,VIX!A:A,VIX!B:B,"",-1) -> 9.53 | F434: =IF(OR(E434="",E433=""),"",E434-E433) -> 0.11 | G434: =_xlfn.XLOOKUP(A434,'DGS10'!A:A,'DGS10'!B:B,"",-1) -> 2.39 | H434: =IF(OR(G434="",G433=""),"",G434-G433) -> 0.04 | I434: =_xlfn.XLOOKUP(A434,T10Y3M!A:A,T10Y3M!B:B,"",-1) -> 1.01 | J434: =_xlfn.XLOOKUP(A434,BAMLC0A4CBBB!A:A,BAMLC0A4CBBB!B:B,"",-1) -> 1.3 | K434: =_xlfn.XLOOKUP(A434,CPIAUCSL!A:A,CPIAUCSL!B:B,"",-1) -> 247.805 | L434: =_xlfn.XLOOKUP(A434,DFF!A:A,DFF!B:B,"",-1) -> 1.42 | M434: =_xlfn.XLOOKUP(A434,'DGS2'!A:A,'DGS2'!B:B,"",-1) -> 1.84 | N434: =IF(OR(M434="",M433=""),"",M434-M433) -> 0 | O434: =IF(OR(B435="",B434=""),"",(B435/B434)-1) -> -0.0032302911 | P434: =IF(O434="","",IF(O434>0,1,0)) -> 0 | Q434: =IF(O434="","",IF(O434>0.003,1,IF(O434<-0.003,-1,0))) -> -1 | R434: 58.11
A435: 43088 | B435: 2681.47 | C435: =IF(OR(B435="",B434=""),"",(B435/B434)-1) -> -0.0032302911 | D435: =IF(OR(B435="",B432=""),"",(B435/B432)-1) -> 0.011108555 | E435: =_xlfn.XLOOKUP(A435,VIX!A:A,VIX!B:B,"",-1) -> 10.03 | F435: =IF(OR(E435="",E434=""),"",E435-E434) -> 0.5 | G435: =_xlfn.XLOOKUP(A435,'DGS10'!A:A,'DGS10'!B:B,"",-1) -> 2.46 | H435: =IF(OR(G435="",G434=""),"",G435-G434) -> 0.07 | I435: =_xlfn.XLOOKUP(A435,T10Y3M!A:A,T10Y3M!B:B,"",-1) -> 1.09 | J435: =_xlfn.XLOOKUP(A435,BAMLC0A4CBBB!A:A,BAMLC0A4CBBB!B:B,"",-1) -> 1.29 | K435: =_xlfn.XLOOKUP(A435,CPIAUCSL!A:A,CPIAUCSL!B:B,"",-1) -> 247.805 | L435: =_xlfn.XLOOKUP(A435,DFF!A:A,DFF!B:B,"",-1) -> 1.42 | M435: =_xlfn.XLOOKUP(A435,'DGS2'!A:A,'DGS2'!B:B,"",-1) -> 1.87 | N435: =IF(OR(M435="",M434=""),"",M435-M434) -> 0.03 | O435: =IF(OR(B436="",B435=""),"",(B436/B435)-1) -> -0.0008279041 | P435: =IF(O435="","",IF(O435>0,1,0)) -> 0 | Q435: =IF(O435="","",IF(O435>0.003,1,IF(O435<-0.003,-1,0))) -> 0 | R435: 57.99
A436: 43089 | B436: 2679.25 | C436: =IF(OR(B436="",B435=""),"",(B436/B435)-1) -> -0.0008279041 | D436: =IF(OR(B436="",B433=""),"",(B436/B433)-1) -> 0.001285592 | E436: =_xlfn.XLOOKUP(A436,VIX!A:A,VIX!B:B,"",-1) -> 9.72 | F436: =IF(OR(E436="",E435=""),"",E436-E435) -> -0.31 | G436: =_xlfn.XLOOKUP(A436,'DGS10'!A:A,'DGS10'!B:B,"",-1) -> 2.49 | H436: =IF(OR(G436="",G435=""),"",G436-G435) -> 0.03 | I436: =_xlfn.XLOOKUP(A436,T10Y3M!A:A,T10Y3M!B:B,"",-1) -> 1.11 | J436: =_xlfn.XLOOKUP(A436,BAMLC0A4CBBB!A:A,BAMLC0A4CBBB!B:B,"",-1) -> 1.28 | K436: =_xlfn.XLOOKUP(A436,CPIAUCSL!A:A,CPIAUCSL!B:B,"",-1) -> 247.805 | L436: =_xlfn.XLOOKUP(A436,DFF!A:A,DFF!B:B,"",-1) -> 1.42 | M436: =_xlfn.XLOOKUP(A436,'DGS2'!A:A,'DGS2'!B:B,"",-1) -> 1.87 | N436: =IF(OR(M436="",M435=""),"",M436-M435) -> 0 | O436: =IF(OR(B437="",B436=""),"",(B437/B436)-1) -> 0.0019856303 | P436: =IF(O436="","",IF(O436>0,1,0)) -> 1 | Q436: =IF(O436="","",IF(O436>0.003,1,IF(O436<-0.003,-1,0))) -> 0 | R436: 57.3
A437: 43090 | B437: 2684.57 | C437: =IF(OR(B437="",B436=""),"",(B437/B436)-1) -> 0.0019856303 | D437: =IF(OR(B437="",B434=""),"",(B437/B434)-1) -> -0.0020779433 | E437: =_xlfn.XLOOKUP(A437,VIX!A:A,VIX!B:B,"",-1) -> 9.62 | F437: =IF(OR(E437="",E436=""),"",E437-E436) -> -0.1 | G437: =_xlfn.XLOOKUP(A437,'DGS10'!A:A,'DGS10'!B:B,"",-1) -> 2.48 | H437: =IF(OR(G437="",G436=""),"",G437-G436) -> -0.01 | I437: =_xlfn.XLOOKUP(A437,T10Y3M!A:A,T10Y3M!B:B,"",-1) -> 1.13 | J437: =_xlfn.XLOOKUP(A437,BAMLC0A4CBBB!A:A,BAMLC0A4CBBB!B:B,"",-1) -> 1.28 | K437: =_xlfn.XLOOKUP(A437,CPIAUCSL!A:A,CPIAUCSL!B:B,"",-1) -> 247.805 | L437: =_xlfn.XLOOKUP(A437,DFF!A:A,DFF!B:B,"",-1) -> 1.42 | M437: =_xlfn.XLOOKUP(A437,'DGS2'!A:A,'DGS2'!B:B,"",-1) -> 1.89 | N437: =IF(OR(M437="",M436=""),"",M437-M436) -> 0.02 | O437: =IF(OR(B438="",B437=""),"",(B438/B437)-1) -> -0.00045817393 | P437: =IF(O437="","",IF(O437>0,1,0)) -> 0 | Q437: =IF(O437="","",IF(O437>0.003,1,IF(O437<-0.003,-1,0))) -> 0 | R437: 57.4
A438: 43091 | B438: 2683.34 | C438: =IF(OR(B438="",B437=""),"",(B438/B437)-1) -> -0.00045817393 | D438: =IF(OR(B438="",B435=""),"",(B438/B435)-1) -> 0.00069737868 | E438: =_xlfn.XLOOKUP(A438,VIX!A:A,VIX!B:B,"",-1) -> 9.9 | F438: =IF(OR(E438="",E437=""),"",E438-E437) -> 0.28 | G438: =_xlfn.XLOOKUP(A438,'DGS10'!A:A,'DGS10'!B:B,"",-1) -> 2.48 | H438: =IF(OR(G438="",G437=""),"",G438-G437) -> 0 | I438: =_xlfn.XLOOKUP(A438,T10Y3M!A:A,T10Y3M!B:B,"",-1) -> 1.15 | J438: =_xlfn.XLOOKUP(A438,BAMLC0A4CBBB!A:A,BAMLC0A4CBBB!B:B,"",-1) -> 1.28 | K438: =_xlfn.XLOOKUP(A438,CPIAUCSL!A:A,CPIAUCSL!B:B,"",-1) -> 247.805 | L438: =_xlfn.XLOOKUP(A438,DFF!A:A,DFF!B:B,"",-1) -> 1.42 | M438: =_xlfn.XLOOKUP(A438,'DGS2'!A:A,'DGS2'!B:B,"",-1) -> 1.91 | N438: =IF(OR(M438="",M437=""),"",M438-M437) -> 0.02 | O438: =IF(OR(B439="",B438=""),"",(B439/B438)-1) -> -0.0010583825 | P438: =IF(O438="","",IF(O438>0,1,0)) -> 0 | Q438: =IF(O438="","",IF(O438>0.003,1,IF(O438<-0.003,-1,0))) -> 0 | R438: 58.36
A439: 43095 | B439: 2680.5 | C439: =IF(OR(B439="",B438=""),"",(B439/B438)-1) -> -0.0010583825 | D439: =IF(OR(B439="",B436=""),"",(B439/B436)-1) -> 0.00046654847 | E439: =_xlfn.XLOOKUP(A439,VIX!A:A,VIX!B:B,"",-1) -> 10.25 | F439: =IF(OR(E439="",E438=""),"",E439-E438) -> 0.35 | G439: =_xlfn.XLOOKUP(A439,'DGS10'!A:A,'DGS10'!B:B,"",-1) -> 2.47 | H439: =IF(OR(G439="",G438=""),"",G439-G438) -> -0.01 | I439: =_xlfn.XLOOKUP(A439,T10Y3M!A:A,T10Y3M!B:B,"",-1) -> 1 | J439: =_xlfn.XLOOKUP(A439,BAMLC0A4CBBB!A:A,BAMLC0A4CBBB!B:B,"",-1) -> 1.28 | K439: =_xlfn.XLOOKUP(A439,CPIAUCSL!A:A,CPIAUCSL!B:B,"",-1) -> 247.805 | L439: =_xlfn.XLOOKUP(A439,DFF!A:A,DFF!B:B,"",-1) -> 1.42 | M439: =_xlfn.XLOOKUP(A439,'DGS2'!A:A,'DGS2'!B:B,"",-1) -> 1.92 | N439: =IF(OR(M439="",M438=""),"",M439-M438) -> 0.01 | O439: =IF(OR(B440="",B439=""),"",(B440/B439)-1) -> 0.00079089722 | P439: =IF(O439="","",IF(O439>0,1,0)) -> 1 | Q439: =IF(O439="","",IF(O439>0.003,1,IF(O439<-0.003,-1,0))) -> 0 | R439: 57.47
A440: 43096 | B440: 2682.62 | C440: =IF(OR(B440="",B439=""),"",(B440/B439)-1) -> 0.00079089722 | D440: =IF(OR(B440="",B437=""),"",(B440/B437)-1) -> -0.00072637331 | E440: =_xlfn.XLOOKUP(A440,VIX!A:A,VIX!B:B,"",-1) -> 10.47 | F440: =IF(OR(E440="",E439=""),"",E440-E439) -> 0.22 | G440: =_xlfn.XLOOKUP(A440,'DGS10'!A:A,'DGS10'!B:B,"",-1) -> 2.42 | H440: =IF(OR(G440="",G439=""),"",G440-G439) -> -0.05 | I440: =_xlfn.XLOOKUP(A440,T10Y3M!A:A,T10Y3M!B:B,"",-1) -> 0.98 | J440: =_xlfn.XLOOKUP(A440,BAMLC0A4CBBB!A:A,BAMLC0A4CBBB!B:B,"",-1) -> 1.28 | K440: =_xlfn.XLOOKUP(A440,CPIAUCSL!A:A,CPIAUCSL!B:B,"",-1) -> 247.805 | L440: =_xlfn.XLOOKUP(A440,DFF!A:A,DFF!B:B,"",-1) -> 1.42 | M440: =_xlfn.XLOOKUP(A440,'DGS2'!A:A,'DGS2'!B:B,"",-1) -> 1.89 | N440: =IF(OR(M440="",M439=""),"",M440-M439) -> -0.03 | O440: =IF(OR(B441="",B440=""),"",(B441/B440)-1) -> 0.0018340279 | P440: =IF(O440="","",IF(O440>0,1,0)) -> 1 | Q440: =IF(O440="","",IF(O440>0.003,1,IF(O440<-0.003,-1,0))) -> 0 | R440: 57.62
A441: 43097 | B441: 2687.54 | C441: =IF(OR(B441="",B440=""),"",(B441/B440)-1) -> 0.0018340279 | D441: =IF(OR(B441="",B438=""),"",(B441/B438)-1) -> 0.0015652135 | E441: =_xlfn.XLOOKUP(A441,VIX!A:A,VIX!B:B,"",-1) -> 10.18 | F441: =IF(OR(E441="",E440=""),"",E441-E440) -> -0.29 | G441: =_xlfn.XLOOKUP(A441,'DGS10'!A:A,'DGS10'!B:B,"",-1) -> 2.43 | H441: =IF(OR(G441="",G440=""),"",G441-G440) -> 0.01 | I441: =_xlfn.XLOOKUP(A441,T10Y3M!A:A,T10Y3M!B:B,"",-1) -> 1.04 | J441: =_xlfn.XLOOKUP(A441,BAMLC0A4CBBB!A:A,BAMLC0A4CBBB!B:B,"",-1) -> 1.27 | K441: =_xlfn.XLOOKUP(A441,CPIAUCSL!A:A,CPIAUCSL!B:B,"",-1) -> 247.805 | L441: =_xlfn.XLOOKUP(A441,DFF!A:A,DFF!B:B,"",-1) -> 1.42 | M441: =_xlfn.XLOOKUP(A441,'DGS2'!A:A,'DGS2'!B:B,"",-1) -> 1.91 | N441: =IF(OR(M441="",M440=""),"",M441-M440) -> 0.02 | O441: =IF(OR(B442="",B441=""),"",(B442/B441)-1) -> -0.0051831787 | P441: =IF(O441="","",IF(O441>0,1,0)) -> 0 | Q441: =IF(O441="","",IF(O441>0.003,1,IF(O441<-0.003,-1,0))) -> -1 | R441: 55.96
A442: 43098 | B442: 2673.61 | C442: =IF(OR(B442="",B441=""),"",(B442/B441)-1) -> -0.0051831787 | D442: =IF(OR(B442="",B439=""),"",(B442/B439)-1) -> -0.002570416 | E442: =_xlfn.XLOOKUP(A442,VIX!A:A,VIX!B:B,"",-1) -> 11.04 | F442: =IF(OR(E442="",E441=""),"",E442-E441) -> 0.86 | G442: =_xlfn.XLOOKUP(A442,'DGS10'!A:A,'DGS10'!B:B,"",-1) -> 2.4 | H442: =IF(OR(G442="",G441=""),"",G442-G441) -> -0.03 | I442: =_xlfn.XLOOKUP(A442,T10Y3M!A:A,T10Y3M!B:B,"",-1) -> 1.01 | J442: =_xlfn.XLOOKUP(A442,BAMLC0A4CBBB!A:A,BAMLC0A4CBBB!B:B,"",-1) -> 1.28 | K442: =_xlfn.XLOOKUP(A442,CPIAUCSL!A:A,CPIAUCSL!B:B,"",-1) -> 247.805 | L442: =_xlfn.XLOOKUP(A442,DFF!A:A,DFF!B:B,"",-1) -> 1.33 | M442: =_xlfn.XLOOKUP(A442,'DGS2'!A:A,'DGS2'!B:B,"",-1) -> 1.89 | N442: =IF(OR(M442="",M441=""),"",M442-M441) -> -0.02 | O442: =IF(OR(B443="",B442=""),"",(B443/B442)-1) -> 0.0083033801 | P442: =IF(O442="","",IF(O442>0,1,0)) -> 1 | Q442: =IF(O442="","",IF(O442>0.003,1,IF(O442<-0.003,-1,0))) -> 1 | R442: 56.69
A443: 43102 | B443: 2695.81 | C443: =IF(OR(B443="",B442=""),"",(B443/B442)-1) -> 0.0083033801 | D443: =IF(OR(B443="",B440=""),"",(B443/B440)-1) -> 0.004916835 | E443: =_xlfn.XLOOKUP(A443,VIX!A:A,VIX!B:B,"",-1) -> 9.77 | F443: =IF(OR(E443="",E442=""),"",E443-E442) -> -1.27 | G443: =_xlfn.XLOOKUP(A443,'DGS10'!A:A,'DGS10'!B:B,"",-1) -> 2.46 | H443: =IF(OR(G443="",G442=""),"",G443-G442) -> 0.06 | I443: =_xlfn.XLOOKUP(A443,T10Y3M!A:A,T10Y3M!B:B,"",-1) -> 1.02 | J443: =_xlfn.XLOOKUP(A443,BAMLC0A4CBBB!A:A,BAMLC0A4CBBB!B:B,"",-1) -> 1.28 | K443: =_xlfn.XLOOKUP(A443,CPIAUCSL!A:A,CPIAUCSL!B:B,"",-1) -> 248.859 | L443: =_xlfn.XLOOKUP(A443,DFF!A:A,DFF!B:B,"",-1) -> 1.42 | M443: =_xlfn.XLOOKUP(A443,'DGS2'!A:A,'DGS2'!B:B,"",-1) -> 1.92 | N443: =IF(OR(M443="",M442=""),"",M443-M442) -> 0.03 | O443: =IF(OR(B444="",B443=""),"",(B444/B443)-1) -> 0.0063988189 | P443: =IF(O443="","",IF(O443>0,1,0)) -> 1 | Q443: =IF(O443="","",IF(O443>0.003,1,IF(O443<-0.003,-1,0))) -> 1 | R443: 57.36
A444: 43103 | B444: 2713.06 | C444: =IF(OR(B444="",B443=""),"",(B444/B443)-1) -> 0.0063988189 | D444: =IF(OR(B444="",B441=""),"",(B444/B441)-1) -> 0.0094956726 | E444: =_xlfn.XLOOKUP(A444,VIX!A:A,VIX!B:B,"",-1) -> 9.15 | F444: =IF(OR(E444="",E443=""),"",E444-E443) -> -0.62 | G444: =_xlfn.XLOOKUP(A444,'DGS10'!A:A,'DGS10'!B:B,"",-1) -> 2.44 | H444: =IF(OR(G444="",G443=""),"",G444-G443) -> -0.02 | I444: =_xlfn.XLOOKUP(A444,T10Y3M!A:A,T10Y3M!B:B,"",-1) -> 1.03 | J444: =_xlfn.XLOOKUP(A444,BAMLC0A4CBBB!A:A,BAMLC0A4CBBB!B:B,"",-1) -> 1.27 | K444: =_xlfn.XLOOKUP(A444,CPIAUCSL!A:A,CPIAUCSL!B:B,"",-1) -> 248.859 | L444: =_xlfn.XLOOKUP(A444,DFF!A:A,DFF!B:B,"",-1) -> 1.42 | M444: =_xlfn.XLOOKUP(A444,'DGS2'!A:A,'DGS2'!B:B,"",-1) -> 1.94 | N444: =IF(OR(M444="",M443=""),"",M444-M443) -> 0.02 | O444: =IF(OR(B445="",B444=""),"",(B445/B444)-1) -> 0.0040286614 | P444: =IF(O444="","",IF(O444>0,1,0)) -> 1 | Q444: =IF(O444="","",IF(O444>0.003,1,IF(O444<-0.003,-1,0))) -> 1 | R444: 57.99
... A453: 43117 | B453: 2802.56 | C453: =IF(OR(B453="",B452=""),"",(B453/B452)-1) -> 0.0094150021 | D453: =IF(OR(B453="",B450=""),"",(B453/B450)-1) -> 0.012646519 | E453: =_xlfn.XLOOKUP(A453,VIX!A:A,VIX!B:B,"",-1) -> 11.91 | F453: =IF(OR(E453="",E452=""),"",E453-E452) -> 0.25 | G453: =_xlfn.XLOOKUP(A453,'DGS10'!A:A,'DGS10'!B:B,"",-1) -> 2.57 | H453: =IF(OR(G453="",G452=""),"",G453-G452) -> 0.03 | I453: =_xlfn.XLOOKUP(A453,T10Y3M!A:A,T10Y3M!B:B,"",-1) -> 1.13 | J453: =_xlfn.XLOOKUP(A453,BAMLC0A4CBBB!A:A,BAMLC0A4CBBB!B:B,"",-1) -> 1.21 | K453: =_xlfn.XLOOKUP(A453,CPIAUCSL!A:A,CPIAUCSL!B:B,"",-1) -> 248.859 | L453: =_xlfn.XLOOKUP(A453,DFF!A:A,DFF!B:B,"",-1) -> 1.42 | M453: =_xlfn.XLOOKUP(A453,'DGS2'!A:A,'DGS2'!B:B,"",-1) -> 2.05 | N453: =IF(OR(M453="",M452=""),"",M453-M452) -> 0.02 | O453: =IF(OR(B454="",B453=""),"",(B454/B453)-1) -> -0.0016163793 | P453: =IF(O453="","",IF(O453>0,1,0)) -> 0 | Q453: =IF(O453="","",IF(O453>0.003,1,IF(O453<-0.003,-1,0))) -> 0 | R453: 58.47
A454: 43118 | B454: 2798.03 | C454: =IF(OR(B454="",B453=""),"",(B454/B453)-1) -> -0.0016163793 | D454: =IF(OR(B454="",B451=""),"",(B454/B451)-1) -> 0.0042315091 | E454: =_xlfn.XLOOKUP(A454,VIX!A:A,VIX!B:B,"",-1) -> 12.22 | F454: =IF(OR(E454="",E453=""),"",E454-E453) -> 0.31 | G454: =_xlfn.XLOOKUP(A454,'DGS10'!A:A,'DGS10'!B:B,"",-1) -> 2.62 | H454: =IF(OR(G454="",G453=""),"",G454-G453) -> 0.05 | I454: =_xlfn.XLOOKUP(A454,T10Y3M!A:A,T10Y3M!B:B,"",-1) -> 1.17 | J454: =_xlfn.XLOOKUP(A454,BAMLC0A4CBBB!A:A,BAMLC0A4CBBB!B:B,"",-1) -> 1.21 | K454: =_xlfn.XLOOKUP(A454,CPIAUCSL!A:A,CPIAUCSL!B:B,"",-1) -> 248.859 | L454: =_xlfn.XLOOKUP(A454,DFF!A:A,DFF!B:B,"",-1) -> 1.42 | M454: =_xlfn.XLOOKUP(A454,'DGS2'!A:A,'DGS2'!B:B,"",-1) -> 2.05 | N454: =IF(OR(M454="",M453=""),"",M454-M453) -> 0 | O454: =IF(OR(B455="",B454=""),"",(B455/B454)-1) -> 0.0043852282 | P454: =IF(O454="","",IF(O454>0,1,0)) -> 1 | Q454: =IF(O454="","",IF(O454>0.003,1,IF(O454<-0.003,-1,0))) -> 1
A455: 43119 | B455: 2810.3 | C455: =IF(OR(B455="",B454=""),"",(B455/B454)-1) -> 0.0043852282 | D455: =IF(OR(B455="",B452=""),"",(B455/B452)-1) -> 0.012202765 | E455: =_xlfn.XLOOKUP(A455,VIX!A:A,VIX!B:B,"",-1) -> 11.27 | F455: =IF(OR(E455="",E454=""),"",E455-E454) -> -0.95 | G455: =_xlfn.XLOOKUP(A455,'DGS10'!A:A,'DGS10'!B:B,"",-1) -> 2.64 | H455: =IF(OR(G455="",G454=""),"",G455-G454) -> 0.02 | I455: =_xlfn.XLOOKUP(A455,T10Y3M!A:A,T10Y3M!B:B,"",-1) -> 1.2 | J455: =_xlfn.XLOOKUP(A455,BAMLC0A4CBBB!A:A,BAMLC0A4CBBB!B:B,"",-1) -> 1.21 | K455: =_xlfn.XLOOKUP(A455,CPIAUCSL!A:A,CPIAUCSL!B:B,"",-1) -> 248.859 | L455: =_xlfn.XLOOKUP(A455,DFF!A:A,DFF!B:B,"",-1) -> 1.42 | M455: =_xlfn.XLOOKUP(A455,'DGS2'!A:A,'DGS2'!B:B,"",-1) -> 2.06 | N455: =IF(OR(M455="",M454=""),"",M455-M454) -> 0.01 | O455: =IF(OR(B456="",B455=""),"",(B456/B455)-1) -> 0.0080667544 | P455: =IF(O455="","",IF(O455>0,1,0)) -> 1 | Q455: =IF(O455="","",IF(O455>0.003,1,IF(O455<-0.003,-1,0))) -> 1 | R455: 59.97
A456: 43122 | B456: 2832.97 | C456: =IF(OR(B456="",B455=""),"",(B456/B455)-1) -> 0.0080667544 | D456: =IF(OR(B456="",B453=""),"",(B456/B453)-1) -> 0.010850794 | E456: =_xlfn.XLOOKUP(A456,VIX!A:A,VIX!B:B,"",-1) -> 11.03 | F456: =IF(OR(E456="",E455=""),"",E456-E455) -> -0.24 | G456: =_xlfn.XLOOKUP(A456,'DGS10'!A:A,'DGS10'!B:B,"",-1) -> 2.66 | H456: =IF(OR(G456="",G455=""),"",G456-G455) -> 0.02 | I456: =_xlfn.XLOOKUP(A456,T10Y3M!A:A,T10Y3M!B:B,"",-1) -> 1.22 | J456: =_xlfn.XLOOKUP(A456,BAMLC0A4CBBB!A:A,BAMLC0A4CBBB!B:B,"",-1) -> 1.21 | K456: =_xlfn.XLOOKUP(A456,CPIAUCSL!A:A,CPIAUCSL!B:B,"",-1) -> 248.859 | L456: =_xlfn.XLOOKUP(A456,DFF!A:A,DFF!B:B,"",-1) -> 1.42 | M456: =_xlfn.XLOOKUP(A456,'DGS2'!A:A,'DGS2'!B:B,"",-1) -> 2.08 | N456: =IF(OR(M456="",M455=""),"",M456-M455) -> 0.02 | O456: =IF(OR(B457="",B456=""),"",(B457/B456)-1) -> 0.0021743965 | P456: =IF(O456="","",IF(O456>0,1,0)) -> 1 | Q456: =IF(O456="","",IF(O456>0.003,1,IF(O456<-0.003,-1,0))) -> 0 | R456: 59.64
A457: 43123 | B457: 2839.13 | C457: =IF(OR(B457="",B456=""),"",(B457/B456)-1) -> 0.0021743965 | D457: =IF(OR(B457="",B454=""),"",(B457/B454)-1) -> 0.014688906 | E457: =_xlfn.XLOOKUP(A457,VIX!A:A,VIX!B:B,"",-1) -> 11.1 | F457: =IF(OR(E457="",E456=""),"",E457-E456) -> 0.07 | G457: =_xlfn.XLOOKUP(A457,'DGS10'!A:A,'DGS10'!B:B,"",-1) -> 2.63 | H457: =IF(OR(G457="",G456=""),"",G457-G456) -> -0.03 | I457: =_xlfn.XLOOKUP(A457,T10Y3M!A:A,T10Y3M!B:B,"",-1) -> 1.19 | J457: =_xlfn.XLOOKUP(A457,BAMLC0A4CBBB!A:A,BAMLC0A4CBBB!B:B,"",-1) -> 1.21 | K457: =_xlfn.XLOOKUP(A457,CPIAUCSL!A:A,CPIAUCSL!B:B,"",-1) -> 248.859 | L457: =_xlfn.XLOOKUP(A457,DFF!A:A,DFF!B:B,"",-1) -> 1.42 | M457: =_xlfn.XLOOKUP(A457,'DGS2'!A:A,'DGS2'!B:B,"",-1) -> 2.06 | N457: =IF(OR(M457="",M456=""),"",M457-M456) -> -0.02 | O457: =IF(OR(B458="",B457=""),"",(B458/B457)-1) -> -0.00056003071 | P457: =IF(O457="","",IF(O457>0,1,0)) -> 0 | Q457: =IF(O457="","",IF(O457>0.003,1,IF(O457<-0.003,-1,0))) -> 0 | R457: 59.84
A458: 43124 | B458: 2837.54 | C458: =IF(OR(B458="",B457=""),"",(B458/B457)-1) -> -0.00056003071 | D458: =IF(OR(B458="",B455=""),"",(B458/B455)-1) -> 0.0096929153 | E458: =_xlfn.XLOOKUP(A458,VIX!A:A,VIX!B:B,"",-1) -> 11.47 | F458: =IF(OR(E458="",E457=""),"",E458-E457) -> 0.37 | G458: =_xlfn.XLOOKUP(A458,'DGS10'!A:A,'DGS10'!B:B,"",-1) -> 2.65 | H458: =IF(OR(G458="",G457=""),"",G458-G457) -> 0.02 | I458: =_xlfn.XLOOKUP(A458,T10Y3M!A:A,T10Y3M!B:B,"",-1) -> 1.22 | J458: =_xlfn.XLOOKUP(A458,BAMLC0A4CBBB!A:A,BAMLC0A4CBBB!B:B,"",-1) -> 1.2 | K458: =_xlfn.XLOOKUP(A458,CPIAUCSL!A:A,CPIAUCSL!B:B,"",-1) -> 248.859 | L458: =_xlfn.XLOOKUP(A458,DFF!A:A,DFF!B:B,"",-1) -> 1.42 | M458: =_xlfn.XLOOKUP(A458,'DGS2'!A:A,'DGS2'!B:B,"",-1) -> 2.08 | N458: =IF(OR(M458="",M457=""),"",M458-M457) -> 0.02 | O458: =IF(OR(B459="",B458=""),"",(B459/B458)-1) -> 0.00060263468 | P458: =IF(O458="","",IF(O458>0,1,0)) -> 1 | Q458: =IF(O458="","",IF(O458>0.003,1,IF(O458<-0.003,-1,0))) -> 0 | R458: 60.42
A459: 43125 | B459: 2839.25 | C459: =IF(OR(B459="",B458=""),"",(B459/B458)-1) -> 0.00060263468 | D459: =IF(OR(B459="",B456=""),"",(B459/B456)-1) -> 0.0022167549 | E459: =_xlfn.XLOOKUP(A459,VIX!A:A,VIX!B:B,"",-1) -> 11.58 | F459: =IF(OR(E459="",E458=""),"",E459-E458) -> 0.11 | G459: =_xlfn.XLOOKUP(A459,'DGS10'!A:A,'DGS10'!B:B,"",-1) -> 2.63 | H459: =IF(OR(G459="",G458=""),"",G459-G458) -> -0.02 | I459: =_xlfn.XLOOKUP(A459,T10Y3M!A:A,T10Y3M!B:B,"",-1) -> 1.21 | J459: =_xlfn.XLOOKUP(A459,BAMLC0A4CBBB!A:A,BAMLC0A4CBBB!B:B,"",-1) -> 1.2 | K459: =_xlfn.XLOOKUP(A459,CPIAUCSL!A:A,CPIAUCSL!B:B,"",-1) -> 248.859 | L459: =_xlfn.XLOOKUP(A459,DFF!A:A,DFF!B:B,"",-1) -> 1.42 | M459: =_xlfn.XLOOKUP(A459,'DGS2'!A:A,'DGS2'!B:B,"",-1) -> 2.08 | N459: =IF(OR(M459="",M458=""),"",M459-M458) -> 0 | O459: =IF(OR(B460="",B459=""),"",(B460/B459)-1) -> 0.011841155 | P459: =IF(O459="","",IF(O459>0,1,0)) -> 1 | Q459: =IF(O459="","",IF(O459>0.003,1,IF(O459<-0.003,-1,0))) -> 1
A460: 43126 | B460: 2872.87 | C460: =IF(OR(B460="",B459=""),"",(B460/B459)-1) -> 0.011841155 | D460: =IF(OR(B460="",B457=""),"",(B460/B457)-1) -> 0.011883922 | E460: =_xlfn.XLOOKUP(A460,VIX!A:A,VIX!B:B,"",-1) -> 11.08 | F460: =IF(OR(E460="",E459=""),"",E460-E459) -> -0.5 | G460: =_xlfn.XLOOKUP(A460,'DGS10'!A:A,'DGS10'!B:B,"",-1) -> 2.66 | H460: =IF(OR(G460="",G459=""),"",G460-G459) -> 0.03 | I460: =_xlfn.XLOOKUP(A460,T10Y3M!A:A,T10Y3M!B:B,"",-1) -> 1.25 | J460: =_xlfn.XLOOKUP(A460,BAMLC0A4CBBB!A:A,BAMLC0A4CBBB!B:B,"",-1) -> 1.18 | K460: =_xlfn.XLOOKUP(A460,CPIAUCSL!A:A,CPIAUCSL!B:B,"",-1) -> 248.859 | L460: =_xlfn.XLOOKUP(A460,DFF!A:A,DFF!B:B,"",-1) -> 1.42 | M460: =_xlfn.XLOOKUP(A460,'DGS2'!A:A,'DGS2'!B:B,"",-1) -> 2.13 | N460: =IF(OR(M460="",M459=""),"",M460-M459) -> 0.05 | O460: =IF(OR(B461="",B460=""),"",(B461/B460)-1) -> -0.006731944 | P460: =IF(O460="","",IF(O460>0,1,0)) -> 0 | Q460: =IF(O460="","",IF(O460>0.003,1,IF(O460<-0.003,-1,0))) -> -1 | R460: 60.37
A461: 43129 | B461: 2853.53 | C461: =IF(OR(B461="",B460=""),"",(B461/B460)-1) -> -0.006731944 | D461: =IF(OR(B461="",B458=""),"",(B461/B458)-1) -> 0.0056351629 | E461: =_xlfn.XLOOKUP(A461,VIX!A:A,VIX!B:B,"",-1) -> 13.84 | F461: =IF(OR(E461="",E460=""),"",E461-E460) -> 2.76 | G461: =_xlfn.XLOOKUP(A461,'DGS10'!A:A,'DGS10'!B:B,"",-1) -> 2.7 | H461: =IF(OR(G461="",G460=""),"",G461-G460) -> 0.04 | I461: =_xlfn.XLOOKUP(A461,T10Y3M!A:A,T10Y3M!B:B,"",-1) -> 1.26 | J461: =_xlfn.XLOOKUP(A461,BAMLC0A4CBBB!A:A,BAMLC0A4CBBB!B:B,"",-1) -> 1.17 | K461: =_xlfn.XLOOKUP(A461,CPIAUCSL!A:A,CPIAUCSL!B:B,"",-1) -> 248.859 | L461: =_xlfn.XLOOKUP(A461,DFF!A:A,DFF!B:B,"",-1) -> 1.42 | M461: =_xlfn.XLOOKUP(A461,'DGS2'!A:A,'DGS2'!B:B,"",-1) -> 2.11 | N461: =IF(OR(M461="",M460=""),"",M461-M460) -> -0.02 | O461: =IF(OR(B462="",B461=""),"",(B462/B461)-1) -> -0.010898782 | P461: =IF(O461="","",IF(O461>0,1,0)) -> 0 | Q461: =IF(O461="","",IF(O461>0.003,1,IF(O461<-0.003,-1,0))) -> -1 | R461: 61.63
A462: 43130 | B462: 2822.43 | C462: =IF(OR(B462="",B461=""),"",(B462/B461)-1) -> -0.010898782 | D462: =IF(OR(B462="",B459=""),"",(B462/B459)-1) -> -0.0059240997 | E462: =_xlfn.XLOOKUP(A462,VIX!A:A,VIX!B:B,"",-1) -> 14.79 | F462: =IF(OR(E462="",E461=""),"",E462-E461) -> 0.95 | G462: =_xlfn.XLOOKUP(A462,'DGS10'!A:A,'DGS10'!B:B,"",-1) -> 2.73 | H462: =IF(OR(G462="",G461=""),"",G462-G461) -> 0.03 | I462: =_xlfn.XLOOKUP(A462,T10Y3M!A:A,T10Y3M!B:B,"",-1) -> 1.29 | J462: =_xlfn.XLOOKUP(A462,BAMLC0A4CBBB!A:A,BAMLC0A4CBBB!B:B,"",-1) -> 1.17 | K462: =_xlfn.XLOOKUP(A462,CPIAUCSL!A:A,CPIAUCSL!B:B,"",-1) -> 248.859 | L462: =_xlfn.XLOOKUP(A462,DFF!A:A,DFF!B:B,"",-1) -> 1.42 | M462: =_xlfn.XLOOKUP(A462,'DGS2'!A:A,'DGS2'!B:B,"",-1) -> 2.13 | N462: =IF(OR(M462="",M461=""),"",M462-M461) -> 0.02 | O462: =IF(OR(B463="",B462=""),"",(B463/B462)-1) -> 0.00048894038 | P462: =IF(O462="","",IF(O462>0,1,0)) -> 1 | Q462: =IF(O462="","",IF(O462>0.003,1,IF(O462<-0.003,-1,0))) -> 0 | R462: 62.01
...

Sheet CRUDE OIL PRICES
A1: Date | B1: Closing Value
A2: 31414 | B2: 25.56
A3: 31415 | B3: 26
A4: 31418 | B4: 26.53
A5: 31419 | B5: 25.85
A6: 31420 | B6: 25.87
A7: 31421 | B7: 26.03
A8: 31422 | B8: 25.65
A9: 31425 | B9: 25.08
A10: 31426 | B10: 24.97
A11: 31427 | B11: 25.18
A12: 31428 | B12: 23.98
A13: 31429 | B13: 23.63
... A8061: 43061 | B8061: 58.02
A8062: 43062
A8063: 43063 | B8063: 58.95
A8064: 43066 | B8064: 58.11
A8065: 43067 | B8065: 57.99
A8066: 43068 | B8066: 57.3
A8067: 43069 | B8067: 57.4
A8068: 43070 | B8068: 58.36
A8069: 43073 | B8069: 57.47
A8070: 43074 | B8070: 57.62
A8071: 43075 | B8071: 55.96
A8072: 43076 | B8072: 56.69
A8073: 43077 | B8073: 57.36
A8074: 43080 | B8074: 57.99
... A8083: 43091 | B8083: 58.47
A8084: 43094
A8085: 43095 | B8085: 59.97
A8086: 43096 | B8086: 59.64
A8087: 43097 | B8087: 59.84
A8088: 43098 | B8088: 60.42
A8089: 43101
A8090: 43102 | B8090: 60.37
A8091: 43103 | B8091: 61.63
A8092: 43104 | B8092: 62.01
A8093: 43105 | B8093: 61.44
A8094: 43108 | B8094: 61.73
A8095: 43109 | B8095: 62.96
...

Sheet VIX
A1: observation_date | B1: VIXCLS
A2: 42461 | B2: 13.1
A3: 42464 | B3: 14.12
A4: 42465 | B4: 15.42
A5: 42466 | B5: 14.09
A6: 42467 | B6: 16.16
A7: 42468 | B7: 15.36
A8: 42471 | B8: 16.26
A9: 42472 | B9: 14.85
A10: 42473 | B10: 13.84
A11: 42474 | B11: 13.72
A12: 42475 | B12: 13.62
A13: 42478 | B13: 13.35
... A42: 42517 | B42: 13.12
A43: 42520
A44: 42521 | B44: 14.19
A45: 42522 | B45: 14.2
A46: 42523 | B46: 13.63
A47: 42524 | B47: 13.47
A48: 42527 | B48: 13.65
A49: 42528 | B49: 14.05
A50: 42529 | B50: 14.08
A51: 42530 | B51: 14.64
A52: 42531 | B52: 17.03
A53: 42534 | B53: 20.97
A54: 42535 | B54: 20.5
A55: 42536 | B55: 20.14
... A67: 42552 | B67: 14.77
A68: 42555
A69: 42556 | B69: 15.58
A70: 42557 | B70: 14.96
A71: 42558 | B71: 14.76
A72: 42559 | B72: 13.2
A73: 42562 | B73: 13.54
A74: 42563 | B74: 13.55
A75: 42564 | B75: 13.04
A76: 42565 | B76: 12.82
A77: 42566 | B77: 12.67
A78: 42569 | B78: 12.44
A79: 42570 | B79: 11.97
...

Sheet DGS10
A1: observation_date | B1: DGS10
A2: 42464 | B2: 1.78
A3: 42465 | B3: 1.73
A4: 42466 | B4: 1.76
A5: 42467 | B5: 1.7
A6: 42468 | B6: 1.72
A7: 42471 | B7: 1.73
A8: 42472 | B8: 1.79
A9: 42473 | B9: 1.77
A10: 42474 | B10: 1.8
A11: 42475 | B11: 1.76
A12: 42478 | B12: 1.78
A13: 42479 | B13: 1.79
... A41: 42517 | B41: 1.85
A42: 42520
A43: 42521 | B43: 1.84
A44: 42522 | B44: 1.85
A45: 42523 | B45: 1.81
A46: 42524 | B46: 1.71
A47: 42527 | B47: 1.73
A48: 42528 | B48: 1.72
A49: 42529 | B49: 1.71
A50: 42530 | B50: 1.68
A51: 42531 | B51: 1.64
A52: 42534 | B52: 1.62
A53: 42535 | B53: 1.62
A54: 42536 | B54: 1.6
... A66: 42552 | B66: 1.46
A67: 42555
A68: 42556 | B68: 1.37
A69: 42557 | B69: 1.38
A70: 42558 | B70: 1.4
A71: 42559 | B71: 1.37
A72: 42562 | B72: 1.43
A73: 42563 | B73: 1.53
A74: 42564 | B74: 1.48
A75: 42565 | B75: 1.53
A76: 42566 | B76: 1.6
A77: 42569 | B77: 1.59
A78: 42570 | B78: 1.56
...

Sheet T10Y3M
A1: observation_date | B1: T10Y3M
A2: 42464 | B2: 1.55
A3: 42465 | B3: 1.5
A4: 42466 | B4: 1.53
A5: 42467 | B5: 1.47
A6: 42468 | B6: 1.49
A7: 42471 | B7: 1.5
A8: 42472 | B8: 1.57
A9: 42473 | B9: 1.54
A10: 42474 | B10: 1.58
A11: 42475 | B11: 1.54
A12: 42478 | B12: 1.56
A13: 42479 | B13: 1.58
... A41: 42517 | B41: 1.53
A42: 42520
A43: 42521 | B43: 1.5
A44: 42522 | B44: 1.55
A45: 42523 | B45: 1.52
A46: 42524 | B46: 1.41
A47: 42527 | B47: 1.45
A48: 42528 | B48: 1.44
A49: 42529 | B49: 1.47
A50: 42530 | B50: 1.42
A51: 42531 | B51: 1.38
A52: 42534 | B52: 1.35
A53: 42535 | B53: 1.35
A54: 42536 | B54: 1.34
... A66: 42552 | B66: 1.18
A67: 42555
A68: 42556 | B68: 1.09
A69: 42557 | B69: 1.11
A70: 42558 | B70: 1.11
A71: 42559 | B71: 1.09
A72: 42562 | B72: 1.12
A73: 42563 | B73: 1.24
A74: 42564 | B74: 1.17
A75: 42565 | B75: 1.21
A76: 42566 | B76: 1.28
A77: 42569 | B77: 1.27
A78: 42570 | B78: 1.25
...

Sheet BAMLC0A4CBBB
A1: observation_date | B1: BAMLC0A4CBBB
A2: 42464 | B2: 2.3
A3: 42465 | B3: 2.31
A4: 42466 | B4: 2.3
A5: 42467 | B5: 2.31
A6: 42468 | B6: 2.31
A7: 42471 | B7: 2.3
A8: 42472 | B8: 2.28
A9: 42473 | B9: 2.26
A10: 42474 | B10: 2.23
A11: 42475 | B11: 2.22
A12: 42478 | B12: 2.21
A13: 42479 | B13: 2.18
... A193: 42727 | B193: 1.64
A194: 42730
A195: 42731 | B195: 1.64
A196: 42732 | B196: 1.64
A197: 42733 | B197: 1.63
A198: 42734 | B198: 1.64
A199: 42735 | B199: 1.66
A200: 42737
A201: 42738 | B201: 1.64
A202: 42739 | B202: 1.63
A203: 42740 | B203: 1.64
A204: 42741 | B204: 1.63
A205: 42744 | B205: 1.63
A206: 42745 | B206: 1.63
A207: 42746 | B207: 1.64
A208: 42747 | B208: 1.64
A209: 42748 | B209: 1.63
A210: 42751 | B210: 1.63
A211: 42752 | B211: 1.63
A212: 42753 | B212: 1.63
... A273: 42838 | B273: 1.58
A274: 42839
A275: 42842 | B275: 1.58
A276: 42843 | B276: 1.59
A277: 42844 | B277: 1.59
A278: 42845 | B278: 1.58
A279: 42846 | B279: 1.58
...

Sheet CPIAUCSL
A1: observation_date | B1: CPIAUCSL
A2: 42401 | B2: 237.336
A3: 42430 | B3: 238.08
A4: 42461 | B4: 238.992
A5: 42491 | B5: 239.557
A6: 42522 | B6: 240.222
A7: 42552 | B7: 240.101
A8: 42583 | B8: 240.545
A9: 42614 | B9: 241.176
A10: 42644 | B10: 241.741
A11: 42675 | B11: 242.026
A12: 42705 | B12: 242.637
A13: 42736 | B13: 243.618
... A117: 45901 | B117: 324.245
A118: 45931
A119: 45962 | B119: 325.063
A120: 45992 | B120: 326.031
A121: 46023 | B121: 326.588
A122: 46054 | B122: 327.46

Sheet DFF
A1: observation_date | B1: DFF
A2: 42462 | B2: 0.37
A3: 42463 | B3: 0.37
A4: 42464 | B4: 0.37
A5: 42465 | B5: 0.37
A6: 42466 | B6: 0.37
A7: 42467 | B7: 0.37
A8: 42468 | B8: 0.37
A9: 42469 | B9: 0.37
A10: 42470 | B10: 0.37
A11: 42471 | B11: 0.37
A12: 42472 | B12: 0.37
A13: 42473 | B13: 0.37
... A3654: 46114 | B3654: 3.64

Sheet DGS2
A1: observation_date | B1: DGS2
A2: 42464 | B2: 0.75
A3: 42465 | B3: 0.72
A4: 42466 | B4: 0.73
A5: 42467 | B5: 0.7
A6: 42468 | B6: 0.7
A7: 42471 | B7: 0.7
A8: 42472 | B8: 0.74
A9: 42473 | B9: 0.75
A10: 42474 | B10: 0.77
A11: 42475 | B11: 0.74
A12: 42478 | B12: 0.75
A13: 42479 | B13: 0.77
... A41: 42517 | B41: 0.9
A42: 42520
A43: 42521 | B43: 0.87
A44: 42522 | B44: 0.91
A45: 42523 | B45: 0.89
A46: 42524 | B46: 0.78
A47: 42527 | B47: 0.8
A48: 42528 | B48: 0.78
A49: 42529 | B49: 0.78
A50: 42530 | B50: 0.77
A51: 42531 | B51: 0.73
A52: 42534 | B52: 0.73
A53: 42535 | B53: 0.74
A54: 42536 | B54: 0.69
... A66: 42552 | B66: 0.59
A67: 42555
A68: 42556 | B68: 0.56
A69: 42557 | B69: 0.58
A70: 42558 | B70: 0.58
A71: 42559 | B71: 0.61
A72: 42562 | B72: 0.66
A73: 42563 | B73: 0.69
A74: 42564 | B74: 0.68
A75: 42565 | B75: 0.68
A76: 42566 | B76: 0.71
A77: 42569 | B77: 0.68
A78: 42570 | B78: 0.7
...
